<?xml version="1.0" ?>
<!-- =================================================================================== -->
<!-- |    This document was autogenerated by xacro from kr20.xacro                     | -->
<!-- |    EDITING THIS FILE BY HAND IS NOT RECOMMENDED                                 | -->
<!-- =================================================================================== -->
<robot name="kr20">
  <!-- END - Include -->
  <!-- World frame (for Gazebo) -->
  <link name="world"/>
  <!-- Arm fixed to world frame  -->
  <joint name="world__base" type="fixed">
    <parent link="world"/>
    <child link="base"/>
    <origin rpy="0 0 0" xyz="0 0 0"/>
  </joint>
  <link name="base">
    <inertial>
      <mass value="157.633"/>
      <origin rpy="0 0 0" xyz="0 0 0"/>
      <inertia ixx="13.235" ixy="0" ixz="0" iyy="13.235" iyz="0" izz="9.655"/>
    </inertial>
    <collision>
      <origin rpy="0 0 0" xyz="0 0 0"/>
      <geometry>
        <mesh filename="package://kuka_kr20_description/meshes/base_co.stl" scale="0.00001 0.00001 0.00001"/>
      </geometry>
    </collision>
    <visual>
      <origin rpy="0 0 0" xyz="0 0 0"/>
      <geometry>
        <mesh filename="package://kuka_kr20_description/meshes/base_co.stl" scale="0.00001 0.00001 0.00001"/>
      </geometry>
      <material name="Orange"/>
    </visual>
  </link>
  <material name="Orange">
    <color rgba="0.95 0.5 0.15 1.0"/>
  </material>
  <material name="Grey">
    <color rgba="0.7 0.7 0.7 1.0"/>
  </material>
  <material name="Black">
    <color rgba="0.0 0.0 0.0 1.0"/>
  </material>
  <gazebo reference="base">
    <material>Gazebo/Black</material>
  </gazebo>
  <gazebo reference="link01">
    <material>Gazebo/Orange</material>
  </gazebo>
  <gazebo reference="link02">
    <material>Gazebo/Orange</material>
  </gazebo>
  <gazebo reference="link03">
    <material>Gazebo/Orange</material>
  </gazebo>
  <gazebo reference="link04">
    <material>Gazebo/Orange</material>
  </gazebo>
  <gazebo reference="link05">
    <material>Gazebo/Orange</material>
  </gazebo>
  <gazebo reference="link06">
    <material>Gazebo/Orange</material>
  </gazebo>
  <gazebo reference="gripper">
    <material>Gazebo/Black</material>
  </gazebo>
  <gazebo reference="gripper_left">
    <material>Gazebo/White</material>
    <mu1>1.0</mu1>
    <mu2>1.0</mu2>
    <kp>1000000.0</kp>
    <kd>1.0</kd>
    <minDepth>0.001</minDepth>
  </gazebo>
  <gazebo reference="gripper_right">
    <material>Gazebo/White</material>
    <mu1>1.0</mu1>
    <mu2>1.0</mu2>
    <kp>1000000.0</kp>
    <kd>1.0</kd>
    <minDepth>0.001</minDepth>
  </gazebo>
  <!-- BEGIN - Robot description -->
  <joint name="base__link01" type="prismatic">
    <axis xyz="0 0 1"/>
    <limit effort="1000" lower="0" upper="0.65" velocity="0.5"/>
    <origin rpy="0 0 1.5708" xyz="-0.9 0 0"/>
    <parent link="base"/>
    <child link="link01"/>
  </joint>
  <transmission name="trans_base__link01">
    <type>transmission_interface/SimpleTransmission</type>
    <joint name="base__link01">
      <hardwareInterface>hardware_interface/PositionJointInterface</hardwareInterface>
    </joint>
    <actuator name="motor_base__link01">
      <hardwareInterface>hardware_interface/PositionJointInterface</hardwareInterface>
      <mechanicalReduction>100</mechanicalReduction>
    </actuator>
  </transmission>
  <link name="link01">
    <inertial>
      <mass value="30.633"/>
      <origin rpy="0 0 0" xyz="0 0 0"/>
      <inertia ixx="13.235" ixy="0" ixz="0" iyy="13.235" iyz="0" izz="9.655"/>
    </inertial>
    <collision>
      <origin rpy="0 0 0" xyz="0 0 0"/>
      <geometry>
        <mesh filename="package://kuka_kr20_description/meshes/base_22.stl" scale="0.00001 0.00001 0.00001"/>
      </geometry>
    </collision>
    <visual>
      <origin rpy="0 0 0" xyz="0 0 0"/>
      <geometry>
        <mesh filename="package://kuka_kr20_description/meshes/base_22.stl" scale="0.00001 0.00001 0.00001"/>
      </geometry>
      <material name="Grey"/>
    </visual>
  </link>
  <joint name="link01__link02" type="revolute">
    <axis xyz="0 0 1"/>
    <limit effort="1000" lower="-3" upper="3" velocity="0.5"/>
    <origin rpy="1.5708 0 3.1416" xyz="0 0 0.3"/>
    <parent link="link01"/>
    <child link="link02"/>
  </joint>
  <transmission name="trans_link01__link02">
    <type>transmission_interface/SimpleTransmission</type>
    <joint name="link01__link02">
      <hardwareInterface>hardware_interface/PositionJointInterface</hardwareInterface>
    </joint>
    <actuator name="motor_link01__link02">
      <hardwareInterface>hardware_interface/PositionJointInterface</hardwareInterface>
      <mechanicalReduction>100</mechanicalReduction>
    </actuator>
  </transmission>
  <link name="link02">
    <inertial>
      <mass value="30.633"/>
      <origin rpy="0 0 0" xyz="0 0 0"/>
      <inertia ixx="13.235" ixy="0" ixz="0" iyy="13.235" iyz="0" izz="9.655"/>
    </inertial>
    <collision>
      <origin rpy="0 0 0" xyz="0 0 0"/>
      <geometry>
        <mesh filename="package://kuka_kr20_description/meshes/link1.stl" scale="0.001 0.001 0.001"/>
      </geometry>
    </collision>
    <visual>
      <origin rpy="0 0 0" xyz="0 0 0"/>
      <geometry>
        <mesh filename="package://kuka_kr20_description/meshes/link1.stl" scale="0.001 0.001 0.001"/>
      </geometry>
      <material name="Orange"/>
    </visual>
  </link>
  <joint name="link02__link03" type="revolute">
    <axis xyz="0 1 0"/>
    <limit effort="1000" lower="-1.5708" upper="1.7453" velocity="0.5"/>
    <origin rpy="1.5708 0 -1.5708" xyz="0.160 -0.095 0.220"/>
    <parent link="link02"/>
    <child link="link03"/>
  </joint>
  <transmission name="trans_link02__link03">
    <type>transmission_interface/SimpleTransmission</type>
    <joint name="link02__link03">
      <hardwareInterface>hardware_interface/PositionJointInterface</hardwareInterface>
    </joint>
    <actuator name="motor_link02__link03">
      <hardwareInterface>hardware_interface/PositionJointInterface</hardwareInterface>
      <mechanicalReduction>100</mechanicalReduction>
    </actuator>
  </transmission>
  <link name="link03">
    <inertial>
      <mass value="10"/>
      <origin rpy="0 0 0" xyz="0 0 0"/>
      <inertia ixx="10" ixy="0" ixz="0" iyy="10" iyz="0" izz="10"/>
    </inertial>
    <collision>
      <origin rpy="0 0 0" xyz="0 0 0"/>
      <geometry>
        <mesh filename="package://kuka_kr20_description/meshes/link2_p.stl" scale="0.0001 0.0001 0.0001"/>
      </geometry>
    </collision>
    <visual>
      <origin rpy="0 0 0" xyz="0 0 0"/>
      <geometry>
        <mesh filename="package://kuka_kr20_description/meshes/link2_p.stl" scale="0.0001 0.0001 0.0001"/>
      </geometry>
      <material name="Orange"/>
    </visual>
  </link>
  <joint name="link03__link04" type="prismatic">
    <axis xyz="1 0 0"/>
    <limit effort="1000" lower="-0.95" upper="0" velocity="0.5"/>
    <origin rpy="0 0 0" xyz="-0.14 0.07 0.830"/>
    <parent link="link03"/>
    <child link="link04"/>
  </joint>
  <transmission name="trans_link03__link04">
    <type>transmission_interface/SimpleTransmission</type>
    <joint name="link03__link04">
      <hardwareInterface>hardware_interface/PositionJointInterface</hardwareInterface>
    </joint>
    <actuator name="motor_link03__link04">
      <hardwareInterface>hardware_interface/PositionJointInterface</hardwareInterface>
      <mechanicalReduction>100</mechanicalReduction>
    </actuator>
  </transmission>
  <link name="link04">
    <inertial>
      <mass value="7"/>
      <origin rpy="0 0 0" xyz="0 0 0"/>
      <inertia ixx="5" ixy="0" ixz="0" iyy="5" iyz="0" izz="5"/>
    </inertial>
    <collision>
      <origin rpy="0 0 0" xyz="0 0 0"/>
      <geometry>
        <mesh filename="package://kuka_kr20_description/meshes/link3_ppp.stl" scale="0.00001 0.00001 0.00001"/>
      </geometry>
    </collision>
    <visual>
      <origin rpy="0 0 0" xyz="0 0 0"/>
      <geometry>
        <mesh filename="package://kuka_kr20_description/meshes/link3_ppp.stl" scale="0.00001 0.00001 0.00001"/>
      </geometry>
      <material name="Orange"/>
    </visual>
  </link>
  <joint name="link04__link05" type="revolute">
    <axis xyz="0 1 0"/>
    <limit effort="1000" lower="-3.0" upper="3.0" velocity="0.5"/>
    <origin rpy="0 1.5708 -1.5708" xyz="1.21 0.001 0.001"/>
    <parent link="link04"/>
    <child link="link05"/>
  </joint>
  <transmission name="trans_link04__link05">
    <type>transmission_interface/SimpleTransmission</type>
    <joint name="link04__link05">
      <hardwareInterface>hardware_interface/PositionJointInterface</hardwareInterface>
    </joint>
    <actuator name="motor_link04__link05">
      <hardwareInterface>hardware_interface/PositionJointInterface</hardwareInterface>
      <mechanicalReduction>100</mechanicalReduction>
    </actuator>
  </transmission>
  <link name="link05">
    <inertial>
      <mass value="2"/>
      <origin rpy="0 0 0" xyz="0 0 0"/>
      <inertia ixx="1" ixy="0" ixz="0" iyy="1" iyz="0" izz="1"/>
    </inertial>
    <collision>
      <origin rpy="0 0 0" xyz="0 0 0"/>
      <geometry>
        <mesh filename="package://kuka_kr20_description/meshes/link4.stl" scale="0.001 0.001 0.001"/>
      </geometry>
    </collision>
    <visual>
      <origin rpy="0 0 0" xyz="0 0 0"/>
      <geometry>
        <mesh filename="package://kuka_kr20_description/meshes/link4.stl" scale="0.001 0.001 0.001"/>
      </geometry>
      <material name="Orange"/>
    </visual>
  </link>
  <joint name="link05__link06" type="revolute">
    <axis xyz="0 -1 0"/>
    <limit effort="1000" lower="-3.0" upper="3.0" velocity="0.5"/>
    <origin rpy="0 0 0" xyz="0.155 0.000 0.000"/>
    <parent link="link05"/>
    <child link="link06"/>
  </joint>
  <transmission name="trans_link05__link06">
    <type>transmission_interface/SimpleTransmission</type>
    <joint name="link05__link06">
      <hardwareInterface>hardware_interface/PositionJointInterface</hardwareInterface>
    </joint>
    <actuator name="motor_link05__link06">
      <hardwareInterface>hardware_interface/PositionJointInterface</hardwareInterface>
      <mechanicalReduction>100</mechanicalReduction>
    </actuator>
  </transmission>
  <link name="link06">
    <inertial>
      <mass value="2"/>
      <origin rpy="0 0 0" xyz="0 0 0"/>
      <inertia ixx="1" ixy="0" ixz="0" iyy="1" iyz="0" izz="1"/>
    </inertial>
    <collision>
      <origin rpy="0 0 0" xyz="0 0 0"/>
      <geometry>
        <mesh filename="package://kuka_kr20_description/meshes/link5.stl" scale="0.001 0.001 0.001"/>
      </geometry>
    </collision>
    <visual>
      <origin rpy="0 0 0" xyz="0 0 0"/>
      <geometry>
        <mesh filename="package://kuka_kr20_description/meshes/link5.stl" scale="0.001 0.001 0.001"/>
      </geometry>
      <material name="Orange"/>
    </visual>
  </link>
  <joint name="link06__gripper" type="revolute">
    <axis xyz="1 0 0"/>
    <limit effort="1000" lower="-1.57" upper="1.57" velocity="0.5"/>
    <origin rpy="0 0 0" xyz="0.115 0 0"/>
    <parent link="link06"/>
    <child link="gripper"/>
  </joint>
  <transmission name="trans_link06__gripper">
    <type>transmission_interface/SimpleTransmission</type>
    <joint name="link06__gripper">
      <hardwareInterface>hardware_interface/PositionJointInterface</hardwareInterface>
    </joint>
    <actuator name="motor_link06__gripper">
      <hardwareInterface>hardware_interface/PositionJointInterface</hardwareInterface>
      <mechanicalReduction>100</mechanicalReduction>
    </actuator>
  </transmission>
  <!-- GRIPPER START HERE -->
  <link name="gripper">
    <inertial>
      <mass value="1"/>
      <origin rpy="0 0 0" xyz="0 0 0"/>
      <inertia ixx="1" ixy="0" ixz="0" iyy="1" iyz="0" izz="1"/>
    </inertial>
    <collision>
      <origin rpy="0 0 0" xyz="0 0 0"/>
      <geometry>
        <mesh filename="package://kuka_kr20_description/meshes/gripper_base.stl" scale="0.001 0.001 0.001"/>
      </geometry>
    </collision>
    <visual>
      <origin rpy="0 0 0" xyz="0 0 0"/>
      <geometry>
        <mesh filename="package://kuka_kr20_description/meshes/gripper_base.stl" scale="0.001 0.001 0.001"/>
      </geometry>
      <material name="Black"/>
    </visual>
  </link>
  <joint name="gripper__gripper_left" type="prismatic">
    <axis xyz="1 0 0"/>
    <limit effort="1000" lower="-0.09" upper="0.0" velocity="0.5"/>
    <origin rpy="0 0 0" xyz="0.04 0.00 0.000"/>
    <parent link="gripper"/>
    <child link="gripper_left"/>
  </joint>
  <transmission name="trans_gripper__gripper_left">
    <type>transmission_interface/SimpleTransmission</type>
    <joint name="gripper__gripper_left">
      <hardwareInterface>hardware_interface/PositionJointInterface</hardwareInterface>
    </joint>
    <actuator name="motor_gripper__gripper_left">
      <hardwareInterface>hardware_interface/PositionJointInterface</hardwareInterface>
      <mechanicalReduction>100</mechanicalReduction>
    </actuator>
  </transmission>
  <link name="gripper_left">
    <inertial>
      <mass value="0.1"/>
      <origin rpy="0 0 0" xyz="0 0 0"/>
      <inertia ixx="1" ixy="0" ixz="0" iyy="1" iyz="0" izz="1"/>
    </inertial>
    <collision>
      <origin rpy="0 0 0" xyz="0 0 0"/>
      <geometry>
        <mesh filename="package://kuka_kr20_description/meshes/gripper_left.stl" scale="0.001 0.001 0.001"/>
      </geometry>
    </collision>
    <visual>
      <origin rpy="0 0 0" xyz="0 0 0"/>
      <geometry>
        <mesh filename="package://kuka_kr20_description/meshes/gripper_left.stl" scale="0.001 0.001 0.001"/>
      </geometry>
      <material name="Grey"/>
    </visual>
  </link>
  <joint name="gripper__gripper_right" type="prismatic">
    <axis xyz="1 0 0"/>
    <limit effort="1000" lower="0.0" upper="0.09" velocity="0.5"/>
    <origin rpy="0 0 0" xyz="0.04 0.00 0.000"/>
    <parent link="gripper"/>
    <child link="gripper_right"/>
  </joint>
  <transmission name="trans_gripper__gripper_right">
    <type>transmission_interface/SimpleTransmission</type>
    <joint name="gripper__gripper_right">
      <hardwareInterface>hardware_interface/PositionJointInterface</hardwareInterface>
    </joint>
    <actuator name="motor_gripper__gripper_right">
      <hardwareInterface>hardware_interface/PositionJointInterface</hardwareInterface>
      <mechanicalReduction>100</mechanicalReduction>
    </actuator>
  </transmission>
  <link name="gripper_right">
    <inertial>
      <mass value="0.1"/>
      <origin rpy="0 0 0" xyz="0 0 0"/>
      <inertia ixx="1" ixy="0" ixz="0" iyy="1" iyz="0" izz="1"/>
    </inertial>
    <collision>
      <origin rpy="0 0 0" xyz="0 0 0"/>
      <geometry>
        <mesh filename="package://kuka_kr20_description/meshes/gripper_right.stl" scale="0.001 0.001 0.001"/>
      </geometry>
    </collision>
    <visual>
      <origin rpy="0 0 0" xyz="0 0 0"/>
      <geometry>
        <mesh filename="package://kuka_kr20_description/meshes/gripper_right.stl" scale="0.001 0.001 0.001"/>
      </geometry>
      <material name="Grey"/>
    </visual>
  </link>
  <!-- GRIPPER END HERE -->
  <!-- END - Robot description -->
  <gazebo>
    <plugin filename="libgazebo_ros_control.so" name="gazebo_ros_control">
      <robotSimType>gazebo_ros_control/DefaultRobotHWSim</robotSimType>
      <robotNamespace>/kr20</robotNamespace>
      <legacyModeNS>true</legacyModeNS>
    </plugin>
  </gazebo>
</robot>

